2021-06-09 11:28:33,620 INFO    MainThread:25493 [internal.py:wandb_internal():64] W&B internal server running at pid: 25493
2021-06-09 11:28:33,622 DEBUG   HandlerThread:25493 [handler.py:handle_request():55] handle_request: check_version
2021-06-09 11:28:33,623 INFO    WriterThread:25493 [datastore.py:open_for_write():77] open: /Users/georgioszefkilis/MLOps_DTU-1/wandb/run-20210609_112832-23aeafg1/run-23aeafg1.wandb
2021-06-09 11:28:33,623 DEBUG   SenderThread:25493 [sender.py:send():117] send: header
2021-06-09 11:28:33,623 DEBUG   SenderThread:25493 [sender.py:send():117] send: request
2021-06-09 11:28:33,624 DEBUG   SenderThread:25493 [sender.py:send_request():126] send_request: check_version
2021-06-09 11:28:33,627 DEBUG   Thread-4  :25493 [connectionpool.py:_new_conn():959] Starting new HTTPS connection (1): pypi.org:443
2021-06-09 11:28:33,669 DEBUG   Thread-4  :25493 [connectionpool.py:_make_request():437] https://pypi.org:443 "GET /pypi/wandb/json HTTP/1.1" 200 57753
2021-06-09 11:28:33,694 DEBUG   SenderThread:25493 [sender.py:send():117] send: run
2021-06-09 11:28:33,698 DEBUG   SenderThread:25493 [cmd.py:execute():818] Popen(['git', 'cat-file', '--batch-check'], cwd=/Users/georgioszefkilis/MLOps_DTU-1, universal_newlines=False, shell=None, istream=<valid stream>)
2021-06-09 11:28:33,715 DEBUG   SenderThread:25493 [connectionpool.py:_new_conn():959] Starting new HTTPS connection (1): api.wandb.ai:443
2021-06-09 11:28:33,880 DEBUG   SenderThread:25493 [connectionpool.py:_make_request():437] https://api.wandb.ai:443 "POST /graphql HTTP/1.1" 403 None
2021-06-09 11:28:33,883 ERROR   SenderThread:25493 [internal_api.py:execute():134] 403 response executing GraphQL.
2021-06-09 11:28:33,883 ERROR   SenderThread:25493 [internal_api.py:execute():135] {"errors":[{"message":"permission denied","path":["upsertBucket"],"extensions":{"code":"PERMISSION_ERROR"}}],"data":{"upsertBucket":null}}
2021-06-09 11:28:34,696 INFO    WriterThread:25493 [datastore.py:close():258] close: /Users/georgioszefkilis/MLOps_DTU-1/wandb/run-20210609_112832-23aeafg1/run-23aeafg1.wandb
2021-06-09 11:28:34,696 INFO    HandlerThread:25493 [handler.py:finish():274] shutting down handler
2021-06-09 11:28:34,697 ERROR   MainThread:25493 [internal.py:wandb_internal():130] Thread SenderThread:
Traceback (most recent call last):
  File "/Users/georgioszefkilis/anaconda3/anaconda3/lib/python3.7/site-packages/wandb/old/retry.py", line 96, in __call__
    result = self._call_fn(*args, **kwargs)
  File "/Users/georgioszefkilis/anaconda3/anaconda3/lib/python3.7/site-packages/wandb/sdk/internal/internal_api.py", line 137, in execute
    six.reraise(*sys.exc_info())
  File "/Users/georgioszefkilis/anaconda3/anaconda3/lib/python3.7/site-packages/six.py", line 703, in reraise
    raise value
  File "/Users/georgioszefkilis/anaconda3/anaconda3/lib/python3.7/site-packages/wandb/sdk/internal/internal_api.py", line 131, in execute
    return self.client.execute(*args, **kwargs)
  File "/Users/georgioszefkilis/anaconda3/anaconda3/lib/python3.7/site-packages/wandb/vendor/gql-0.2.0/gql/client.py", line 52, in execute
    result = self._get_result(document, *args, **kwargs)
  File "/Users/georgioszefkilis/anaconda3/anaconda3/lib/python3.7/site-packages/wandb/vendor/gql-0.2.0/gql/client.py", line 60, in _get_result
    return self.transport.execute(document, *args, **kwargs)
  File "/Users/georgioszefkilis/anaconda3/anaconda3/lib/python3.7/site-packages/wandb/vendor/gql-0.2.0/gql/transport/requests.py", line 39, in execute
    request.raise_for_status()
  File "/Users/georgioszefkilis/anaconda3/anaconda3/lib/python3.7/site-packages/requests/models.py", line 940, in raise_for_status
    raise HTTPError(http_error_msg, response=self)
requests.exceptions.HTTPError: 403 Client Error: Forbidden for url: https://api.wandb.ai/graphql

During handling of the above exception, another exception occurred:

Traceback (most recent call last):
  File "/Users/georgioszefkilis/anaconda3/anaconda3/lib/python3.7/site-packages/wandb/apis/normalize.py", line 24, in wrapper
    return func(*args, **kwargs)
  File "/Users/georgioszefkilis/anaconda3/anaconda3/lib/python3.7/site-packages/wandb/sdk/internal/internal_api.py", line 977, in upsert_run
    response = self.gql(mutation, variable_values=variable_values, **kwargs)
  File "/Users/georgioszefkilis/anaconda3/anaconda3/lib/python3.7/site-packages/wandb/old/retry.py", line 105, in __call__
    if not check_retry_fn(e):
  File "/Users/georgioszefkilis/anaconda3/anaconda3/lib/python3.7/site-packages/wandb/util.py", line 667, in no_retry_auth
    raise CommError("Permission denied, ask the project owner to grant you access")
wandb.errors.error.CommError: Permission denied, ask the project owner to grant you access

During handling of the above exception, another exception occurred:

Traceback (most recent call last):
  File "/Users/georgioszefkilis/anaconda3/anaconda3/lib/python3.7/site-packages/wandb/sdk/internal/internal_util.py", line 34, in run
    self._run()
  File "/Users/georgioszefkilis/anaconda3/anaconda3/lib/python3.7/site-packages/wandb/sdk/internal/internal_util.py", line 61, in _run
    self._process(record)
  File "/Users/georgioszefkilis/anaconda3/anaconda3/lib/python3.7/site-packages/wandb/sdk/internal/internal.py", line 234, in _process
    self._sm.send(record)
  File "/Users/georgioszefkilis/anaconda3/anaconda3/lib/python3.7/site-packages/wandb/sdk/internal/sender.py", line 119, in send
    send_handler(record)
  File "/Users/georgioszefkilis/anaconda3/anaconda3/lib/python3.7/site-packages/wandb/sdk/internal/sender.py", line 485, in send_run
    self._init_run(run, config_value_dict)
  File "/Users/georgioszefkilis/anaconda3/anaconda3/lib/python3.7/site-packages/wandb/sdk/internal/sender.py", line 521, in _init_run
    commit=repo.last_commit,
  File "/Users/georgioszefkilis/anaconda3/anaconda3/lib/python3.7/site-packages/wandb/apis/normalize.py", line 62, in wrapper
    six.reraise(CommError, CommError(message, err), sys.exc_info()[2])
  File "/Users/georgioszefkilis/anaconda3/anaconda3/lib/python3.7/site-packages/six.py", line 702, in reraise
    raise value.with_traceback(tb)
  File "/Users/georgioszefkilis/anaconda3/anaconda3/lib/python3.7/site-packages/wandb/apis/normalize.py", line 24, in wrapper
    return func(*args, **kwargs)
  File "/Users/georgioszefkilis/anaconda3/anaconda3/lib/python3.7/site-packages/wandb/sdk/internal/internal_api.py", line 977, in upsert_run
    response = self.gql(mutation, variable_values=variable_values, **kwargs)
  File "/Users/georgioszefkilis/anaconda3/anaconda3/lib/python3.7/site-packages/wandb/old/retry.py", line 105, in __call__
    if not check_retry_fn(e):
  File "/Users/georgioszefkilis/anaconda3/anaconda3/lib/python3.7/site-packages/wandb/util.py", line 667, in no_retry_auth
    raise CommError("Permission denied, ask the project owner to grant you access")
wandb.errors.error.CommError: Permission denied, ask the project owner to grant you access
2021-06-09 11:28:34,731 DEBUG   raven-sentry.BackgroundWorker:25493 [connectionpool.py:_new_conn():959] Starting new HTTPS connection (1): o151352.ingest.sentry.io:443
2021-06-09 11:28:34,782 DEBUG   raven-sentry.BackgroundWorker:25493 [connectionpool.py:_make_request():437] https://o151352.ingest.sentry.io:443 "POST /api/5288891/store/ HTTP/1.1" 200 41
2021-06-09 11:28:36,732 INFO    MainThread:25493 [internal.py:handle_exit():139] Internal process exited
